<?xml version="1.0" ?>

<robot name="SUV">
  <!--link name="dummy_link"></link-->
  <link
    name="base_link">
    <inertial>
      <origin
        xyz="0.20578 6.7449E-05 0.23392"
        rpy="0 0 0" />
      <mass
        value="90.229" />
      <inertia
        ixx="2.1481"
        ixy="0.004352"
        ixz="0.4205"
        iyy="6.2811"
        iyz="-0.0018801"
        izz="7.2521" />
    </inertial>
    <visual>
      <origin
        xyz="0 0 0"
        rpy="0 0 0" />
      <geometry>
        <mesh
          filename="package://SUV/meshes/base_link.STL" />
      </geometry>
      <material
        name="">
        <color
          rgba="0.79216 0.81961 0.93333 1" />
      </material>
    </visual>
    <!--collision>
      <origin
        xyz="0 0 0"
        rpy="0 0 0" />
      <geometry>
        <mesh
          filename="package://SUV/meshes/base_link.STL" />
      </geometry>
    </collision-->
  </link>
  <!--joint name="dummy_joint" type="fixed">
    <origin rpy="0 0 0" xyz="0 0 0" />
    <parent link="dummy_link"/>
    <child link="base_link"/>
</joint-->

  <link
    name="RearLeftWheel">
    <inertial>
      <origin
        xyz="2.2204E-16 0 2.2204E-16"
        rpy="0 0 0" />
      <mass
        value="1.3962" />
      <inertia
        ixx="0.0051815"
        ixy="-1.0132E-17"
        ixz="-3.1476E-18"
        iyy="0.0090774"
        iyz="-8.3661E-18"
        izz="0.0051815" />
    </inertial>
    <visual>
      <origin
        xyz="0 0 0"
        rpy="0 0 0" />
      <geometry>
        <mesh
          filename="package://SUV/meshes/RearLeftWheel.STL" />
      </geometry>
      <material
        name="">
        <color
          rgba="0.79216 0.81961 0.93333 1" />
      </material>
    </visual>
    <collision>
      <origin
        xyz="0 0 0"
        rpy="0 0 0" />
      <geometry>
        <mesh
          filename="package://SUV/meshes/RearLeftWheel.STL" />
      </geometry>
    </collision>
  </link>
  <joint
    name="RearLeftWheel_Joint"
    type="continuous">
    <origin
      xyz="0 0.2032 0.10144"
      rpy="0 0 0" />
    <parent
      link="base_link" />
    <child
      link="RearLeftWheel" />
    <axis
      xyz="0 1 0" />
  </joint>
  <link
    name="RearRightWheel">
    <inertial>
      <origin
        xyz="2.2204E-16 1.1102E-16 2.2204E-16"
        rpy="0 0 0" />
      <mass
        value="1.3962" />
      <inertia
        ixx="0.0051815"
        ixy="-7.5071E-18"
        ixz="-1.593E-18"
        iyy="0.0090774"
        iyz="-1.7247E-17"
        izz="0.0051815" />
    </inertial>
    <visual>
      <origin
        xyz="0 0 0"
        rpy="0 0 0" />
      <geometry>
        <mesh
          filename="package://SUV/meshes/RearRightWheel.STL" />
      </geometry>
      <material
        name="">
        <color
          rgba="0.79216 0.81961 0.93333 1" />
      </material>
    </visual>
    <collision>
      <origin
        xyz="0 0 0"
        rpy="0 0 0" />
      <geometry>
        <mesh
          filename="package://SUV/meshes/RearRightWheel.STL" />
      </geometry>
    </collision>
  </link>
  <joint
    name="RearRightWheel_Joint"
    type="continuous">
    <origin
      xyz="0 -0.2032 0.10144"
      rpy="0 0 0" />
    <parent
      link="base_link" />
    <child
      link="RearRightWheel" />
    <axis
      xyz="0 1 0" />
  </joint>
  <link
    name="FrontLeftSteer">
    <inertial>
      <origin
        xyz="-1.79856129989275E-14 0.037265343785134 0.000157388248064994"
        rpy="0 0 0" />
      <mass
        value="0.017358141232428" />
      <inertia
        ixx="7.67294854860874E-06"
        ixy="1.58472142546195E-20"
        ixz="-7.86135753705226E-21"
        iyy="7.38363363134266E-07"
        iyz="2.13410869020758E-20"
        izz="7.64761183870118E-06" />
    </inertial>
    <visual>
      <origin
        xyz="0 0 0"
        rpy="0 0 0" />
      <geometry>
        <mesh
          filename="package://SUV/meshes/FrontLeftSteer.STL" />
      </geometry>
      <material
        name="">
        <color
          rgba="0.792156862745098 0.819607843137255 0.933333333333333 1" />
      </material>
    </visual>
    <!--collision>
      <origin
        xyz="0 0 0"
        rpy="0 0 0" />
      <geometry>
        <mesh
          filename="package://SUV/meshes/FrontLeftSteer.STL" />
      </geometry>
    </collision-->
  </link>
  <joint
    name="FrontLeftSteer_Joint"
    type="continuous">
    <origin
      xyz="0.508 0.1397 0.10144"
      rpy="0 0 0" />
    <parent
      link="base_link" />
    <child
      link="FrontLeftSteer" />
    <axis
      xyz="0 0 1" />
  </joint>
  <link
    name="FrontLeftWheel">
    <inertial>
      <origin
        xyz="0 -2.22044604925031E-16 2.22044604925031E-16"
        rpy="0 0 0" />
      <mass
        value="1.39619583298456" />
      <inertia
        ixx="0.0051814826332267"
        ixy="-1.19452155290798E-17"
        ixz="6.85526197351124E-19"
        iyy="0.00907736130581274"
        iyz="-1.30080636187624E-17"
        izz="0.0051814826332267" />
    </inertial>
    <visual>
      <origin
        xyz="0 0 0"
        rpy="0 0 0" />
      <geometry>
        <mesh
          filename="package://SUV/meshes/FrontLeftWheel.STL" />
      </geometry>
      <material
        name="">
        <color
          rgba="0.792156862745098 0.819607843137255 0.933333333333333 1" />
      </material>
    </visual>
    <collision>
      <origin
        xyz="0 0 0"
        rpy="0 0 0" />
      <geometry>
        <mesh
          filename="package://SUV/meshes/FrontLeftWheel.STL" />
      </geometry>
    </collision>
  </link>
  <joint
    name="FrontLeftWheel_Joint"
    type="continuous">
    <origin
      xyz="0 0.0635 0.00015739"
      rpy="0 0 0" />
    <parent
      link="FrontLeftSteer" />
    <child
      link="FrontLeftWheel" />
    <axis
      xyz="0 1 0" />
  </joint>
  <link
    name="FrontRightSteer">
    <inertial>
      <origin
        xyz="-1.1768E-14 -0.037265 0.00015739"
        rpy="0 0 0" />
      <mass
        value="0.017358" />
      <inertia
        ixx="7.6729E-06"
        ixy="1.7249E-20"
        ixz="-8.0895E-21"
        iyy="7.3836E-07"
        iyz="1.3886E-20"
        izz="7.6476E-06" />
    </inertial>
    <visual>
      <origin
        xyz="0 0 0"
        rpy="0 0 0" />
      <geometry>
        <mesh
          filename="package://SUV/meshes/FrontRightSteer.STL" />
      </geometry>
      <material
        name="">
        <color
          rgba="0.79216 0.81961 0.93333 1" />
      </material>
    </visual>
    <!--collision>
      <origin
        xyz="0 0 0"
        rpy="0 0 0" />
      <geometry>
        <mesh
          filename="package://SUV/meshes/FrontRightSteer.STL" />
      </geometry>
    </collision-->
  </link>
  <joint
    name="FrontRightSteer_Joint"
    type="continuous">
    <origin
      xyz="0.508 -0.1397 0.10144"
      rpy="0 0 0" />
    <parent
      link="base_link" />
    <child
      link="FrontRightSteer" />
    <axis
      xyz="0 0 1" />
  </joint>
  <link
    name="FrontRightWheel">
    <inertial>
      <origin
        xyz="2.22044604925031E-16 0 0"
        rpy="0 0 0" />
      <mass
        value="1.39619583298457" />
      <inertia
        ixx="0.00518148263322671"
        ixy="-1.64532585220915E-17"
        ixz="6.38492740808577E-18"
        iyy="0.00907736130581276"
        iyz="-7.53601200300198E-18"
        izz="0.00518148263322672" />
    </inertial>
    <visual>
      <origin
        xyz="0 0 0"
        rpy="0 0 0" />
      <geometry>
        <mesh
          filename="package://SUV/meshes/FrontRightWheel.STL" />
      </geometry>
      <material
        name="">
        <color
          rgba="0.792156862745098 0.819607843137255 0.933333333333333 1" />
      </material>
    </visual>
    <collision>
      <origin
        xyz="0 0 0"
        rpy="0 0 0" />
      <geometry>
        <mesh
          filename="package://SUV/meshes/FrontRightWheel.STL" />
      </geometry>
    </collision>
  </link>
  <joint
    name="FrontRightWheel_Joint"
    type="continuous">
    <origin
      xyz="0 -0.0635 0.00015739"
      rpy="0 0 0" />
    <parent
      link="FrontRightSteer" />
    <child
      link="FrontRightWheel" />
    <axis
      xyz="0 1 0" />
  </joint>
  <link
    name="Hitch1">
    <inertial>
      <origin
        xyz="-0.571383258799901 -1.74917281658971E-07 0.0822815332976223"
        rpy="0 0 0" />
      <mass
        value="5.9801503611173" />
      <inertia
        ixx="0.123019502397971"
        ixy="3.82559087295855E-08"
        ixz="-5.64052916088022E-10"
        iyy="0.438975610025772"
        iyz="-1.38605410830019E-10"
        izz="0.528069911621096" />
    </inertial>
    <visual>
      <origin
        xyz="0 0 0"
        rpy="0 0 0" />
      <geometry>
        <mesh
          filename="package://SUV/meshes/Hitch1.STL" />
      </geometry>
      <material
        name="">
        <color
          rgba="0.792156862745098 0.819607843137255 0.933333333333333 1" />
      </material>
    </visual>
    <!--collision>
      <origin
        xyz="0 0 0"
        rpy="0 0 0" />
      <geometry>
        <mesh
          filename="package://SUV/meshes/Hitch1.STL" />
      </geometry>
    </collision-->
  </link>
  <joint
    name="Hitch1_Joint"
    type="continuous">
    <origin
      xyz="-0.24495 0 0.10144"
      rpy="0 0 0" />
    <parent
      link="base_link" />
    <child
      link="Hitch1" />
    <axis
      xyz="0 0 1" />
  </joint>
  <link
    name="LeftTrailer1">
    <inertial>
      <origin
        xyz="1.66533453693773E-16 -2.22044604925031E-16 0"
        rpy="0 0 0" />
      <mass
        value="1.39619583298456" />
      <inertia
        ixx="0.00518148263322669"
        ixy="-1.49045809926886E-17"
        ixz="-3.49787595846701E-18"
        iyy="0.00907736130581273"
        iyz="-1.60998995089318E-17"
        izz="0.00518148263322669" />
    </inertial>
    <visual>
      <origin
        xyz="0 0 0"
        rpy="0 0 0" />
      <geometry>
        <mesh
          filename="package://SUV/meshes/LeftTrailer1.STL" />
      </geometry>
      <material
        name="">
        <color
          rgba="0.792156862745098 0.819607843137255 0.933333333333333 1" />
      </material>
    </visual>
    <collision>
      <origin
        xyz="0 0 0"
        rpy="0 0 0" />
      <geometry>
        <mesh
          filename="package://SUV/meshes/LeftTrailer1.STL" />
      </geometry>
    </collision>
  </link>
  <joint
    name="LeftTrailer1_Joint"
    type="continuous">
    <origin
      xyz="-0.82362 0.2032 3.2E-05"
      rpy="0 0 0" />
    <parent
      link="Hitch1" />
    <child
      link="LeftTrailer1" />
    <axis
      xyz="0 1 0" />
  </joint>
  <link
    name="RightTrailer1">
    <inertial>
      <origin
        xyz="5.55111512312578E-17 0 2.22044604925031E-16"
        rpy="0 0 0" />
      <mass
        value="1.39619583298456" />
      <inertia
        ixx="0.0051814826332267"
        ixy="-1.65394826681313E-17"
        ixz="-2.40739753654012E-18"
        iyy="0.00907736130581274"
        iyz="-1.54647964627013E-17"
        izz="0.0051814826332267" />
    </inertial>
    <visual>
      <origin
        xyz="0 0 0"
        rpy="0 0 0" />
      <geometry>
        <mesh
          filename="package://SUV/meshes/RightTrailer1.STL" />
      </geometry>
      <material
        name="">
        <color
          rgba="0.792156862745098 0.819607843137255 0.933333333333333 1" />
      </material>
    </visual>
    <collision>
      <origin
        xyz="0 0 0"
        rpy="0 0 0" />
      <geometry>
        <mesh
          filename="package://SUV/meshes/RightTrailer1.STL" />
      </geometry>
    </collision>
  </link>
  <joint
    name="RightTrailer1_Joint"
    type="continuous">
    <origin
      xyz="-0.82362 -0.20574 3.2E-05"
      rpy="0 0 0" />
    <parent
      link="Hitch1" />
    <child
      link="RightTrailer1" />
    <axis
      xyz="0 1 0" />
  </joint>
  <link
    name="Hitch2">
    <inertial>
      <origin
        xyz="-0.5713832587999 -1.74917281547948E-07 0.0822495332976192"
        rpy="0 0 0" />
      <mass
        value="5.98015036111735" />
      <inertia
        ixx="0.123019502397972"
        ixy="3.82559082887827E-08"
        ixz="-5.64053047096979E-10"
        iyy="0.438975610025775"
        iyz="-1.3860532021831E-10"
        izz="0.528069911621099" />
    </inertial>
    <visual>
      <origin
        xyz="0 0 0"
        rpy="0 0 0" />
      <geometry>
        <mesh
          filename="package://SUV/meshes/Hitch2.STL" />
      </geometry>
      <material
        name="">
        <color
          rgba="0.792156862745098 0.819607843137255 0.933333333333333 1" />
      </material>
    </visual>
    <!--collision>
      <origin
        xyz="0 0 0"
        rpy="0 0 0" />
      <geometry>
        <mesh
          filename="package://SUV/meshes/Hitch2.STL" />
      </geometry>
    </collision-->
  </link>
  <joint
    name="Hitch2_Joint"
    type="continuous">
    <origin
      xyz="-0.98102 0 3.2E-05"
      rpy="0 0 0" />
    <parent
      link="Hitch1" />
    <child
      link="Hitch2" />
    <axis
      xyz="0 0 1" />
  </joint>
  <link
    name="LeftTrailer2">
    <inertial>
      <origin
        xyz="0 -2.22044604925031E-16 0"
        rpy="0 0 0" />
      <mass
        value="1.39619583298456" />
      <inertia
        ixx="0.0051814826332267"
        ixy="-1.31981558346315E-17"
        ixz="2.11483834534612E-18"
        iyy="0.00907736130581275"
        iyz="-1.07555294615332E-17"
        izz="0.00518148263322671" />
    </inertial>
    <visual>
      <origin
        xyz="0 0 0"
        rpy="0 0 0" />
      <geometry>
        <mesh
          filename="package://SUV/meshes/LeftTrailer2.STL" />
      </geometry>
      <material
        name="">
        <color
          rgba="0.792156862745098 0.819607843137255 0.933333333333333 1" />
      </material>
    </visual>
    <collision>
      <origin
        xyz="0 0 0"
        rpy="0 0 0" />
      <geometry>
        <mesh
          filename="package://SUV/meshes/LeftTrailer2.STL" />
      </geometry>
    </collision>
  </link>
  <joint
    name="LeftTrailer2_Joint"
    type="continuous">
    <origin
      xyz="-0.82362 0.2032 0"
      rpy="0 0 0" />
    <parent
      link="Hitch2" />
    <child
      link="LeftTrailer2" />
    <axis
      xyz="0 1 0" />
  </joint>
  <link
    name="RightTrailer2">
    <inertial>
      <origin
        xyz="-1.11022302462516E-16 0 2.22044604925031E-16"
        rpy="0 0 0" />
      <mass
        value="1.39619583298456" />
      <inertia
        ixx="0.0051814826332267"
        ixy="-8.24116394978783E-18"
        ixz="-2.53874847422681E-18"
        iyy="0.00907736130581275"
        iyz="-1.66388203000654E-17"
        izz="0.0051814826332267" />
    </inertial>
    <visual>
      <origin
        xyz="0 0 0"
        rpy="0 0 0" />
      <geometry>
        <mesh
          filename="package://SUV/meshes/RightTrailer2.STL" />
      </geometry>
      <material
        name="">
        <color
          rgba="0.792156862745098 0.819607843137255 0.933333333333333 1" />
      </material>
    </visual>
    <collision>
      <origin
        xyz="0 0 0"
        rpy="0 0 0" />
      <geometry>
        <mesh
          filename="package://SUV/meshes/RightTrailer2.STL" />
      </geometry>
    </collision>
  </link>
  <joint
    name="RightTrailer2_Joint"
    type="continuous">
    <origin
      xyz="-0.82362 -0.2032 0"
      rpy="0 0 0" />
    <parent
      link="Hitch2" />
    <child
      link="RightTrailer2" />
    <axis
      xyz="0 1 0" />
  </joint>
  <link
    name="Lidar">
    <!--inertial>
      <origin
        xyz="-0.120223128501902 -0.00175537561410155 -0.208243943487197"
        rpy="0 0 0" />
      <mass
        value="113.393556936072" />
      <inertia
        ixx="3.1110994454595"
        ixy="-0.000788686232497615"
        ixz="-1.24895184371809"
        iyy="50.130632440056"
        iyz="-0.00240162187475082"
        izz="51.5140624958444" />
    </inertial>
    <visual>
      <origin
        xyz="0 0 0"
        rpy="0 0 0" />
      <geometry>
        <mesh
          filename="package://SUV/meshes/Lidar.STL" />
      </geometry>
      <material
        name="">
        <color
          rgba="1 1 1 1" />
      </material>
    </visual>
    <collision>
      <origin
        xyz="0 0 0"
        rpy="0 0 0" />
      <geometry>
        <mesh
          filename="package://SUV/meshes/Lidar.STL" />
      </geometry>
    </collision-->
  </link>
  <joint
    name="Lidar_Joint"
    type="fixed">
    <origin
      xyz="0.0819997270807393 0.00177776795566731 0.423784484115624"
      rpy="0 0 0" />
    <parent
      link="base_link" />
    <child
      link="Lidar" />
    <axis
      xyz="0 0 0" />
  </joint>
  
  
 
  <ros2_control name="GazeboSystem" type="system">
    <hardware>
      <plugin>gazebo_ros2_control/GazeboSystem</plugin>
    </hardware>

    <joint name="FrontLeftWheel_Joint">
      <command_interface name="velocity">
        <param name="min">-1000.0</param>
        <param name="max">1000.0</param>
      </command_interface>
      <state_interface name="position"/>
      <state_interface name="velocity"/>
    </joint>

    <joint name="FrontRightWheel_Joint">
      <command_interface name="velocity">
        <param name="min">-1000.0</param>
        <param name="max">1000.0</param>
      </command_interface>
      <state_interface name="position"/>
      <state_interface name="velocity"/>
    </joint>
   
    <joint name="RearRightWheel_Joint">
      <command_interface name="velocity">
        <param name="min">-1000.0</param>
        <param name="max">1000.0</param>
      </command_interface>
      <state_interface name="position"/>
      <state_interface name="velocity"/>
    </joint>

    <joint name="RearLeftWheel_Joint">
      <command_interface name="velocity">
        <param name="min">-1000.0</param>
        <param name="max">1000.0</param>
      </command_interface>
      <state_interface name="position"/>
      <state_interface name="velocity"/>
    </joint>

    <joint name="LeftTrailer1_Joint">
      <command_interface name="velocity">
        <param name="min">-1000.0</param>
        <param name="max">1000.0</param>
      </command_interface>
      <state_interface name="position"/>
      <state_interface name="velocity"/>
    </joint>

    <joint name="RightTrailer1_Joint">
      <command_interface name="velocity">
        <param name="min">-1000.0</param>
        <param name="max">1000.0</param>
      </command_interface>
      <state_interface name="position"/>
      <state_interface name="velocity"/>
    </joint>

    <joint name="LeftTrailer2_Joint">
      <command_interface name="velocity">
        <param name="min">-1000.0</param>
        <param name="max">1000.0</param>
      </command_interface>
      <state_interface name="position"/>
      <state_interface name="velocity"/>
    </joint>

    <joint name="RightTrailer2_Joint">
      <command_interface name="velocity">
        <param name="min">-1000.0</param>
        <param name="max">1000.0</param>
      </command_interface>
      <state_interface name="position"/>
      <state_interface name="velocity"/>
    </joint>

   
    <joint name="FrontLeftSteer_Joint">
      <command_interface name="position">
        <param name="min">-3.14</param>
        <param name="max">3.14</param>
      </command_interface>
      <state_interface name="position"/>
      <state_interface name="velocity"/>
    </joint>

    <joint name="FrontRightSteer_Joint">
      <command_interface name="position">
        <param name="min">-3.14</param>
        <param name="max">3.14</param>
      </command_interface>
      <state_interface name="position"/>
      <state_interface name="velocity"/>
    </joint>
  </ros2_control>

  <gazebo>
    <plugin filename="libgazebo_ros2_control.so" name="gazebo_ros2_control">
      <parameters>$(find SUV)/config/control.yaml</parameters>
    </plugin>
  </gazebo>

  <!-- Added this plugin just to get the odom, I do not intend to control vehicle using cmd_vel-->
  <gazebo>
    <plugin name="object_controller" filename="libgazebo_ros_planar_move.so">
      <commandTopic>cmd_vel</commandTopic>
      <odometryTopic>odom</odometryTopic>
      <odometryFrame>odom</odometryFrame>
      <odometryRate>20.0</odometryRate>
      <robotBaseFrame>base_footprint</robotBaseFrame>
    </plugin>
  </gazebo>

  <gazebo reference="Lidar">
  <sensor name="lidar" type="ray">
    <pose>0.0 0.0 0.0 0 0 0</pose>
    <always_on>true</always_on>
    <visualize>true</visualize>
    <update_rate>5</update_rate>
    <ray>
      <scan>
        <horizontal>
          <samples>360</samples>
          <resolution>1.00000</resolution>
          <min_angle>0.000000</min_angle>
          <max_angle>6.280000</max_angle>
        </horizontal>
      </scan>
      <range>
        <min>0.120000</min>
        <max>3.5</max>
        <resolution>0.015000</resolution>
      </range>
      <noise>
        <type>gaussian</type>
        <mean>0.0</mean>
        <stddev>0.01</stddev>
      </noise>
    </ray>
    <plugin name="scan" filename="libgazebo_ros_ray_sensor.so">
      <ros>
        <remapping>~/out:=scan</remapping>
      </ros>
      <output_type>sensor_msgs/LaserScan</output_type>
      <frame_name>base_link</frame_name>
    </plugin>
  </sensor>
  </gazebo>
  
  <gazebo reference="base_link">
  <gravity>true</gravity>
  <sensor name="imu_sensor" type="imu">
    <always_on>true</always_on>
    <update_rate>100</update_rate>
    <visualize>true</visualize>
    <topic>__default_topic__</topic>
    <plugin filename="libgazebo_ros_imu_sensor.so" name="imu_plugin">
      <topicName>imu</topicName>
      <bodyName>base_link</bodyName>
      <updateRateHZ>10.0</updateRateHZ>
      <gaussianNoise>0.0</gaussianNoise>
      <xyzOffset>0 0 0</xyzOffset>
      <rpyOffset>0 0 0</rpyOffset>
      <frameName>base_link</frameName>
      <initialOrientationAsReference>false</initialOrientationAsReference>
    </plugin>
    <pose>0 0 0 0 0 0</pose>
  </sensor>
</gazebo>

</robot>













